Workbook
Name a: [1]검토측정!#REF!
Name Actual: #REF!
Name Actual_Date: '[2]Resource Estimation & Tracking'!$O$7
Name b: [1]단계별측정!#REF!
Name change_age: #N/A
Name change_no: #REF!
Name cost_a: #N/A
Name cost_e: #N/A
Name d: [1]단계별측정!#REF!
Name df: [1]검토측정!#REF!
Name e: [1]단계별측정!#REF!
Name effort_change: #N/A
Name effort_review: #N/A
Name effort_rework: #N/A
Name fdsfdsa: [1]소스코드크기측정!#REF!
Name fdsfsda: [1]단계별측정!#REF!
Name Planned: #REF!
Name Planned_Date: '[2]Resource Estimation & Tracking'!$O$6
Name Planned_Total: '[2]Resource Estimation & Tracking'!$O$5
Name req_added: #REF!
Name req_base: #REF!
Name req_changed: #REF!
Name req_deleted: #REF!
Name review_defect: #N/A
Name review_error: #N/A
Name size_code_e: [1]소스코드크기측정!#REF!
Name Total: #REF!
Name total_time: #REF!
Name vr목록: '[3]1. Safety Case'!$J$17:$J$50
Name 목록: '[3]1. Safety Case'!$J$7:$J$50
Name 목록1: '[3]7. DFA 결과'!$K$7:$K$9
Name 목록2: '[3]7. DFA 결과'!$L$7:$L$8
Name 총_Project_기간: '[2]Resource Estimation & Tracking'!$C$10

Sheet Cover
I8: =Cover!F25_ -> #NAME?
C13: Vehicle | E13: : | F13: NX5
C15: Item | E15: : | F15: PLBM
C17: Customer | E17: : | F17: HKMC
C19: Department/Author | E19: : | F19: 전동화SW설계1팀 / 배준역
C21: Document Number | E21: : | F21: =F13&"_"&F15&"-SL_SWE1-DC02" -> NX5_PLBM-SL_SWE1-DC02
C24: Template change Record
C25: Version | D25: Date | E25: Department/Author | H25: Description of Change
C26: 1.0 | D26: 2020.04.01 | E26: 기능안전팀/ 김윤겸, 방지현 | H26: 최초 개정
C27: 1.1 | D27: 2020.04.22 | E27: 기능안전팀/ 김윤겸, 방지현 | H27: 조치 내용' 항목 추가 및 목록 명칭 수정
C28: 1.2 | D28: 2020.06.22 | E28: 기능안전팀/ 김윤겸, 방지현 | H28: - '적용/미적용' 항목 삭제 - 준수율, 부적합율 소수 첫째자리까지 표현 - 관련 문서명 및 버전 - 참석자 관련 역할 정의 - VR 전략 수정 병합하여 작성
C29: 1.3 | D29: 2020.06.30 | E29: 기능안전팀/ 김윤겸, 방지현 | H29: - Sheet 명 수정 - 'Verification Review Report' Sheet 항목 일부 수정 (참석자, 리뷰대상 문서명 및 버전, 사전 점검 자료 저장소, 사전 점검 여부) - 결제창 수정
C30: 1.4 | D30: 2022.02.28 | E30: 기능안전팀/ 김윤겸 | H30: - Verification Review 전략 내용 수정
C31: 1.5 | D31: 2022.04.14 | E31: 기능안전팀/ 김윤겸 | H31: - SYS/ HW/ SW 검증 관련 산출물 Walkthrough Review에 대한 제약 사항 내용 가이드라인에 추가
C32: 1.6 | D32: 2023.03.24 | E32: 기능안전팀/ 박언지 | H32: Summary 시트 수정(PR ID 작성, 상세 심사 내용 작성란 추가 등)
C33: 3 | D33: 2023.03.24 | E33: 기능안전팀/ 박언지 | H33: 템플릿 3.0 개정에 따른 버전업
C34: 3.1 | D34: 2023.11.24 | E34: 기능안전팀/ 임채홍, 정현욱 | H34: Work Product Review Report v3.1 템플릿 적용 - 템플릿 변경에 따른 체크 항목 변경 - 요구사항의 체크내용을 통합하고 각 항목을 상세히 검토 할 수 있도록 수정
C35: 4 | D35: 224.12.31 | E35: 기능안전팀/ 배진호 | H35: Work Product Review Report v4.0 템플릿 적용 - 'Cover'Sheet 수정 - 템플릿 변경에 따른 체크 항목 변경 - 요구사항의 체크내용을 통합하고 각 항목을 상세히 검토 할 수 있도록 수정

Sheet Verification Review Strategy
B1: SL Verification Review Strategy
A4: 1. Verification Review 범위
A5: - 각 프로세스 산출물에 대한 검토 활동을 정의 한다.
A7: 2. Verification Review 수행 방법
A8: - Review는 "Work Product Review Checklist" 기준으로 수행하고, 기능안전팀 프로세스 각 담당자들은 Review 수행 이전에 체크리스트 항목, Review 방법에 대해 작성자 및 Review 참석들에게 가이드를 해야 한다.
A10: - Review는 ASPICE 프로세스가 적용되거나 기능안전의 경우 ASIL B 이상의 아이템인 경우 "Inspection" 방법으로 수행하고, 그 외의 경우에는 "Walkthrough"방법으로 수행한다.
A12: - Review의 주관은 문서 작성자(Author)가 주관 하고, Review 참석자들에게 Review 일주일전에 참석을 요청 한다.
A14: - "Walkthrough"의 경우, 문서 작성자(Author)는 Review 이전에 작성한 산출물에 대해 체크리스트 기반으로 사전 검토 후 참석 한다.
A16: - "Inspection"의 경우, 문서 작성자(Author)는 작성 완료 된 산출물 및 체크리스트를 Review 참석자들에게 Review 일주일전에 배포하고, Review 참석자들은 전달받은 산출물을 체크리스트 기반으로 사전 점검 하여 Review에 참석 한다.
A18: - 산출물 Review 수행 시, Review 수행에 대한 독립성은 다음 기준을 참고 하여, Project plan의 Verification Strategy 수립 시, 반영 한다.
A19: (I0 : 옵션, 다른 사람으로부터, I1 : 필수, 다른 사람으로부터, I2 : 필수, 다른 팀의 사람으로부터, I3 : 필수, 다른 회사의 사람으로부터)
A21: - 각 R&R 별로, (정), (부)의 관계를 가지고 담당자들이 프로세스를 수행 하는 경우에는, Review에는 (정)으로 되어 있는 담당자가 참석하고, (정) 담당자가 Review 참석 불가 할 경우, (부) 담당자가 참석 한다.
A22: Review 진행 조건은, Reviewer가 3인 이상 참석 할 경우, 진행이 가능 하다. (단, 각 Role 별로 1명씩은 필수 참석 해야 되고, (부) 담당자로만 2명 이상으로 구성 될 경우, Review는 진행 하지 않고 연기 한다.)
... A48: 프로젝트마다 마일스톤 및 Lifecycle 운영 전략이 다르므로, 참고로 활용 하고 상세 Review Criteria는 E PM 주관으로 각 프로젝트에서 상세히 정의 한다.

Sheet Verification Review Summary
A1: "Software Requirements Specification" Verification Review Summary
B4: Status of Review
B5: 준수율 (%) | C5: ='Verification Review Report '!O4 -> 1
B6: 부적합 율 (%) | C6: ='Verification Review Report '!Q5 / ('Verification Review Report '!Q4 + 'Verification Review Report '!Q5) -> 0
B18: 부적합 번호 | D18: 부적합 체크리스트 내용 | E18: 상세 심사내용 | F18: 조치 확인자 | G18: Non-conformance ID
B19: {=IFERROR(INDEX(#REF!, MATCH(1, ( COUNTIF('Verification Review Summary'!$B$18:B18,#REF!) = 0) * ("NG" =#REF!), 0)), "")} | D19: =IFERROR(VLOOKUP(B19,#REF!,2,FALSE),"") | E19: =IFERROR(VLOOKUP(B19,#REF!,9,FALSE),"")
B20: {=IFERROR(INDEX(#REF!, MATCH(1, ( COUNTIF('Verification Review Summary'!$B$18:B19,#REF!) = 0) * ("NG" =#REF!), 0)), "")} | D20: =IFERROR(VLOOKUP(B20,#REF!,2,FALSE),"") | E20: =IFERROR(VLOOKUP(B20,#REF!,9,FALSE),"")
B21: {=IFERROR(INDEX(#REF!, MATCH(1, ( COUNTIF('Verification Review Summary'!$B$18:B20,#REF!) = 0) * ("NG" =#REF!), 0)), "")} | D21: =IFERROR(VLOOKUP(B21,#REF!,2,FALSE),"") | E21: =IFERROR(VLOOKUP(B21,#REF!,9,FALSE),"")
B22: {=IFERROR(INDEX(#REF!, MATCH(1, ( COUNTIF('Verification Review Summary'!$B$18:B21,#REF!) = 0) * ("NG" =#REF!), 0)), "")} | D22: =IFERROR(VLOOKUP(B22,#REF!,2,FALSE),"") | E22: =IFERROR(VLOOKUP(B22,#REF!,9,FALSE),"")
B23: {=IFERROR(INDEX(#REF!, MATCH(1, ( COUNTIF('Verification Review Summary'!$B$18:B22,#REF!) = 0) * ("NG" =#REF!), 0)), "")} | D23: =IFERROR(VLOOKUP(B23,#REF!,2,FALSE),"") | E23: =IFERROR(VLOOKUP(B23,#REF!,9,FALSE),"")
B24: {=IFERROR(INDEX(#REF!, MATCH(1, ( COUNTIF('Verification Review Summary'!$B$18:B23,#REF!) = 0) * ("NG" =#REF!), 0)), "")} | D24: =IFERROR(VLOOKUP(B24,#REF!,2,FALSE),"") | E24: =IFERROR(VLOOKUP(B24,#REF!,9,FALSE),"")
B25: {=IFERROR(INDEX(#REF!, MATCH(1, ( COUNTIF('Verification Review Summary'!$B$18:B24,#REF!) = 0) * ("NG" =#REF!), 0)), "")} | D25: =IFERROR(VLOOKUP(B25,#REF!,2,FALSE),"") | E25: =IFERROR(VLOOKUP(B25,#REF!,9,FALSE),"")
B26: {=IFERROR(INDEX(#REF!, MATCH(1, ( COUNTIF('Verification Review Summary'!$B$18:B25,#REF!) = 0) * ("NG" =#REF!), 0)), "")} | D26: =IFERROR(VLOOKUP(B26,#REF!,2,FALSE),"") | E26: =IFERROR(VLOOKUP(B26,#REF!,9,FALSE),"")
B27: {=IFERROR(INDEX(#REF!, MATCH(1, ( COUNTIF('Verification Review Summary'!$B$18:B26,#REF!) = 0) * ("NG" =#REF!), 0)), "")} | D27: =IFERROR(VLOOKUP(B27,#REF!,2,FALSE),"") | E27: =IFERROR(VLOOKUP(B27,#REF!,9,FALSE),"")
B28: {=IFERROR(INDEX(#REF!, MATCH(1, ( COUNTIF('Verification Review Summary'!$B$18:B27,#REF!) = 0) * ("NG" =#REF!), 0)), "")} | D28: =IFERROR(VLOOKUP(B28,#REF!,2,FALSE),"") | E28: =IFERROR(VLOOKUP(B28,#REF!,9,FALSE),"")
B29: {=IFERROR(INDEX(#REF!, MATCH(1, ( COUNTIF('Verification Review Summary'!$B$18:B28,#REF!) = 0) * ("NG" =#REF!), 0)), "")} | D29: =IFERROR(VLOOKUP(B29,#REF!,2,FALSE),"") | E29: =IFERROR(VLOOKUP(B29,#REF!,9,FALSE),"")
B30: {=IFERROR(INDEX(#REF!, MATCH(1, ( COUNTIF('Verification Review Summary'!$B$18:B29,#REF!) = 0) * ("NG" =#REF!), 0)), "")} | D30: =IFERROR(VLOOKUP(B30,#REF!,2,FALSE),"") | E30: =IFERROR(VLOOKUP(B30,#REF!,9,FALSE),"")
... B53: {=IFERROR(INDEX(#REF!, MATCH(1, ( COUNTIF('Verification Review Summary'!$B$18:B52,#REF!) = 0) * ("NG" =#REF!), 0)), "")} | D53: =IFERROR(VLOOKUP(B53,#REF!,2,FALSE),"") | E53: =IFERROR(VLOOKUP(B53,#REF!,9,FALSE),"")

Sheet Verification Review Report 
E1: "Software Requirements Specification" Review Report | N1: Status of Review | R1: 판정 기준
C2: 차종/아이템 | F2: NX5/PLBM | G2: 검토 날짜 및 시간 | H2: 2026.04.09 (14:00~14:30) | N2: 검토타입 | O2: Peer Review | P2: 해당 항목 | Q2: =COUNTIF($K$36:$K$146,"OK")+COUNTIF($K$36:$K$146,"OK But") + COUNTIF($K$36:$K$146, "NG") -> 17 | R2: OK : 체크리스트 문항을 만족
C3: 검토 시점 | F3: P2 | G3: 사전 점검 여부 | H3: X | N3: ASIL | O3: A | P3: 미 해당 항목 | Q3: =COUNTIF($K$36:$K$146,"N/A") -> 64 | R3: OK But : 부적합 사항이 고객 및 관련자와의 협의가 된 상황에서 충분히 수용가능하여 조건부 만족
C4: 리뷰대상 문서명 및 버전 | F4: NX5 PLBM-Software Requirement Specification(v2.10) | N4: 준수율 | O4: =IFERROR(Q4/Q2, "0.0%") -> 1 | P4: 적합 | Q4: =COUNTIF($K$36:$K$146,"OK")+COUNTIF($K$36:$K$146,"OK But") -> 17 | R4: NG : 내용이 미비하여 체크리스트 항목을 만족하지 않는 경우
C5: 리뷰대상 문서 경로 | F5: /HMC_NX5_P-LBM/ | P5: 부적합 | Q5: =COUNTIF($K$36:$K$146,"NG") -> 0 | R5: N/A : 리뷰 시점에 체크리스트 항목이 확인되지 않는 경우 / 미적용인 경우
C6: Pre-Review Report 저장 경로 | F6: X
C7: 적용 프로세스 | F7: A-SPICE+Functional Safety | N7: * 검토 회의 시 발생한 이슈사항 작성 (결함 내용은 작성하지 않는다)
C8: 참석자 | N8: \
C9: 역할 | F9: Role | G9: Responsibility
C10: Author | F10: SW PE1(APP) | G10: 배준역 선임
C11: Reviewer | F11: SW TE(Qualification) | G11: 한승훈 책임
F12: SW PE2 (APP) | G12: 최기원 사원
F13: SW PE3(APP) | G13: 김대호 선임
F14: SW PE4(Static Verification) | G14: 권영준 사원
F15: SW PE | G15: 이호성 선임
F16: SYS PE | G16: 심정현 책임
F17: SW TE(Qualification) | G17: 한승훈 책임
F18: SW PE(BSP) | G18: 이정헌 사원
C19: Moderator (사회자)
C20: Leader (의사결정자) | F20: SW PE3(APP) | G20: 김대호 선임
C21: Recorder (기록자) | F21: SW PE2 (APP) | G21: 최기원 사원
C22: Resolution Reviewer (조치 확인자)
C25: 관련 문서명 및 버전
C26: 산출물 명 | G26: 버전
C27: NX5_PLBM-Software Development Plan | G27: v2.5
C28: NX5_PLBM-System Requirement Specification | G28: v2.11
C29: NX5_PLBM-System Design Specificaiton | G29: v2.11
C30: NX5_PLBM-Hardware Software Interface Specification | G30: v2.3
C31: Safety Mechanism List | G31: v2.3
C32: * 검토 타입이 Inspection인 경우, Moderator가 Reader 역할을 수행하고 Walkthrough인 경우, Author가 Reader 역할을 수행한다.
B35: No | C35: 체크리스트 | I35: 가능 여부 | J35: 의견 | K35: 판정 | L35: 상세 심사 내용
B36: 1 | C36: Software Development Plan 전략에 따라 개발 하였는가? -적절히 정의된 활동, Method, 가이드라인을 준수하여 개발 하였는지? | I36: X | J36: Dev Plan을 import 후 진행하는 것으로 어려움 | K36: N/A | L36: 금번 내용과 동일하며 변경 없음
B37: 2 | C37: 문서의 개발 목적이 정의되어 있으며, 다루고 있는 내용의 범위가 정확하게 기술되어 있는가? (Scope) | I37: O | J37: AI가 충분히 문서에 대한 목적과 정의를 작성할 수 있음 | K37: N/A | L37: 금번 내용과 동일하며 변경 없음
B38: 3 | C38: 문서에서 사용한 용어 및 약어에 대한 적절히 정의가 적절히 정의되어 있는가? (Terms and Abbreviations) - 문서에 작성된 용어 및 약어에 대해 적절히 정의되고 설명 작성 여부 확인 | I38: O | J38: 문서의 작성된 약어를 명기할 수 있음 | K38: N/A | L38: 금번 내용과 동일하며 변경 없음
B39: 4 | C39: Software Requirement Specification 문서 개발에 필요한 모든 참조 대상 문서가 식별되어 적절히 정의되어 있는가? (Reference) - 문서이름, 설명, 버전 및 날짜가 누락없이 참조한 모든 문서를 정의하였는가? - 문서 개발 시 참조한 문서가 최신 버전 상태를 유지하고 있는가? 단, 최신 버전과 구 버전의 참조 내용이 차이가 없는 경우 구 버전 참조 가능함 | I39: x | J39: 최신자 문서를 import해야함. | K39: OK | L39: 상위 문서의 최신 버전을 참조함
B40: 5 | C40: System Requirement Specifiaction에서 SW로 할당한 기능/안전 기능과 Software Diagram에 적절히 정의된 SW Function List, SW Safety Function List가 일관성을 유지 하는가? (Software Diagram) -누락 여부 -불필요한 기능은 없는지? -SW Function/SW Safety Function -비기능의 경우, 그 속성에 따라 표현 되지 않을 수 있다(법률, 성능 등) | I40: O | J40: 일치성 확인은 가능 | K40: N/A | L40: 금번 내용과 동일하며 변경 없음
B41: 6 | C41: System Design Specification에서 적절히 정의된 System Architecture를 기반으로 Software Context Diagram이 일관성있게 적절히 정의 되었는가? (Software Diagram) -누락 여부 -Element, HW-SW Interface의 일관성 -잘못된 적절히 정의는 없는지 | I41: O | J41: 누락여부 정도는 확인 가능 | K41: N/A | L41: 금번 내용과 동일하며 변경 없음
B42: 7 | C42: SW Function List를 기반으로 SW Element가 SW Context Diagram에 모두 적절히 정의되어 있는가? (Software Diagram) | I42: O | J42: 누락여부 정도는 확인 가능 | K42: N/A | L42: 금번 내용과 동일하며 변경 없음
B43: 8 | C43: SW Safety Function List를 기반으로 SW Element가 SW Context Diagram에 모두 적절히 정의되어 있는가? (Software Diagram) | I43: O | J43: 정의도 작성가능으로 보입니다 | K43: N/A | L43: 금번 내용과 동일하며 변경 없음
B44: 9 | C44: 소프트웨어 기능의 Risk 등급이 SW Function Risk Analysis 통해 도출된 결과를 기반으로 작성되어 있는가? (Software Diagram) | I44: X | J44: Function Risk Analysis를 수행하고 그대로 가지고 오는 것이기 때문에 AI가 작성할 이유는 없어 보입니다. Analysis는 설계자의 의견이 반영되어야 합니다. | K44: N/A | L44: 금번 내용과 동일하며 변경 없음
...

Sheet Traceability Report
B6: System Requirements Specification - Software Requirements Specification
B7: HSI Specification - Software Requirements Specification
B8: System Design Specification - Software Requirements Specification

Sheet Technical Feasibility
B3: State Requirements
C4: Normal Mode | D4: NQ5 PE PLBM의 캐리오버이므로 충분히 구현 가능하다.
C5: Sleep Mode | D5: NQ5 PE PLBM의 캐리오버이므로 충분히 구현 가능하다.
C6: Active Mode | D6: NQ5 PE PLBM의 캐리오버이므로 충분히 구현 가능하다.
B7: Transition Requirements
C8: Transition 1 | D8: NQ5 PE PLBM의 캐리오버이므로 충분히 구현 가능하다.
C9: Transition 2 | D9: NQ5 PE PLBM의 캐리오버이므로 충분히 구현 가능하다.
C10: Transition 3 | D10: NQ5 PE PLBM의 캐리오버이므로 충분히 구현 가능하다.
C11: Transition 4 | D11: NQ5 PE PLBM의 캐리오버이므로 충분히 구현 가능하다.
C12: Transition 5 | D12: NQ5 PE PLBM의 캐리오버이므로 충분히 구현 가능하다.
C13: Transition 7 | D13: NQ5 PE PLBM의 캐리오버이므로 충분히 구현 가능하다.
B14: Safe State Requirements
C15: 충/방전 금지(LBM 내부 온도 모니터링 유지) | D15: NQ5 PE PLBM의 캐리오버이므로 충분히 구현 가능하다.
C16: End-User Fail Warning Alert | D16: NQ5 PE PLBM의 캐리오버이므로 충분히 구현 가능하다.
C17: Safe Transition Requirements | D17: NQ5 PE PLBM의 캐리오버이므로 충분히 구현 가능하다.
C18: Transition 6 | D18: NQ5 PE PLBM의 캐리오버이므로 충분히 구현 가능하다.
C19: Transition 8 | D19: NQ5 PE PLBM의 캐리오버이므로 충분히 구현 가능하다.
C20: Transition 9 | D20: NQ5 PE PLBM의 캐리오버이므로 충분히 구현 가능하다.
B21: Interface Requirements
C22: B+_POWER_Moni | D22: NQ5 PE PLBM의 캐리오버이므로 충분히 구현 가능하다.
C23: IGN2_Moni | D23: NQ5 PE PLBM의 캐리오버이므로 충분히 구현 가능하다.
C24: DCDC_Control(ADC) | D24: NQ5 PE PLBM의 캐리오버이므로 충분히 구현 가능하다.
C25: DCDC_Control(GPIO) | D25: NQ5 PE PLBM의 캐리오버이므로 충분히 구현 가능하다.
C26: DCDC_Control(PWM) | D26: NQ5 PE PLBM의 캐리오버이므로 충분히 구현 가능하다.
C27: BTB_OnOff | D27: NQ5 PE PLBM의 캐리오버이므로 충분히 구현 가능하다.
C28: BTB_Volt | D28: NQ5 PE PLBM의 캐리오버이므로 충분히 구현 가능하다.
C29: Cell_Volt_Info | D29: NQ5 PE PLBM의 캐리오버이므로 충분히 구현 가능하다.
C30: Cell_Temp_Info | D30: NQ5 PE PLBM의 캐리오버이므로 충분히 구현 가능하다.
C31: Sum_Cur_Info | D31: NQ5 PE PLBM의 캐리오버이므로 충분히 구현 가능하다.
C32: CAN_Info_Rx | D32: NQ5 PE PLBM의 캐리오버이므로 충분히 구현 가능하다.
C33: CAN_Info_Tx | D33: NQ5 PE PLBM의 캐리오버이므로 충분히 구현 가능하다.
... C54: Reset_Info | D54: NQ5 PE PLBM의 캐리오버이므로 충분히 구현 가능하다.
B55: Functional Requirements
C56: 충전 제어 | D56: NQ5 PE PLBM의 캐리오버이므로 해당 기능의 요구사항들은 충분히 구현 가능하다.
C57: 충전 진입 조건 (30Ah) | D57: NQ5 PE PLBM의 캐리오버이므로 해당 기능의 요구사항들은 충분히 구현 가능하다.
C58: 충전 진입 조건 (주행 중 20Ah 빌트인캠 미적용) | D58: NQ5 PE PLBM의 캐리오버이므로 해당 기능의 요구사항들은 충분히 구현 가능하다.
C59: 충전 진입 조건 (주차 중 20Ah 빌트인캠 미적용) | D59: NQ5 PE PLBM의 캐리오버이므로 해당 기능의 요구사항들은 충분히 구현 가능하다.
C60: 충전 진입 조건 (주행 중20Ah BLTN ONLY 사양) | D60: NQ5 PE PLBM의 캐리오버이므로 해당 기능의 요구사항들은 충분히 구현 가능하다.
C61: 충전 진입 조건 (주차 중20Ah BLTN ONLY 사양) | D61: NQ5 PE PLBM의 캐리오버이므로 해당 기능의 요구사항들은 충분히 구현 가능하다.
C62: 충전 금지 조건 (30Ah) | D62: NQ5 PE PLBM의 캐리오버이므로 해당 기능의 요구사항들은 충분히 구현 가능하다.
...
